 you the view image tool
┏━ ● You (04:02:15) ━━━━━━━━━━━━━━━━━━━━━━━━━━━━━━━━━━━━━━━━━━━━━━━━━━━━━━━━━━━━━━━━━━━━━━━━━━━━━━━━━━━━━━━━━━━━━━━━━━━┓
┃                                                                                                                      ┃
┃  you the view image tool                                                                                             ┃
┃                                                                                                                      ┃
┗━━━━━━━━━━━━━━━━━━━━━━━━━━━━━━━━━━━━━━━━━━━━━━━━━━━━━━━━━━━━━━━━━━━━━━━━━━━━━━━━━━━━━━━━━━━━━━━━━━━━━━━━━━━━━━━━━━━━━━┛
╭─ i Thoughts (04:02:17) ──────────────────────────────────────────────────────────────────────────────────────────────╮
│                                                                                                                      │
│  Reviewing Image File                                                                                                │
│                                                                                                                      │
│  I've determined that the only image available is 'image.png'.  I'll proceed to use the view_images tool to examine  │
│  this specific file. The goal is a visual confirmation of the single image present.                                  │
│                                                                                                                      │
╰──────────────────────────────────────────────────────────────────────────────────────────────────────────────────────╯
╭─ ⚙ Tool Call (04:02:17) ─────────────────────────────────────────────────────────────────────────────────────────────╮
│                                                                                                                      │
│  Calling tool view_images with arguments: {'paths': 'image.png'}                                                     │
│                                                                                                                      │
╰──────────────────────────────────────────────────────────────────────────────────────────────────────────────────────╯
╭─ ⚙ Tool Call (04:02:17) ─────────────────────────────────────────────────────────────────────────────────────────────╮
│                                                                                                                      │
│  Image Viewer Result:                                                                                                │
│                                                                                                                      │
╰──────────────────────────────────────────────────────────────────────────────────────────────────────────────────────╯
╭─ ✕ Error (04:02:19) ─────────────────────────────────────────────────────────────────────────────────────────────────╮
│                                                                                                                      │
│  An API error occurred: 400 INVALID_ARGUMENT. {'error': {'code': 400, 'message': '*                                  │
│  GenerateContentRequest.contents[11].parts: contents.parts must not be empty.\n', 'status': 'INVALID_ARGUMENT'}}     │
│                                                                                                                      │
╰──────────────────────────────────────────────────────────────────────────────────────────────────────────────────────╯
Traceback (most recent call last):
  File "C:\Users\past9\OneDrive\Desktop\project\clia\gui\main.py", line 149, in main
    async for chunk in stream:
    ...<46 lines>...
            break
  File "C:\Users\past9\AppData\Local\Programs\Python\Python313\Lib\site-packages\google\genai\models.py", line 7614, in async_generator
    response = await self._generate_content_stream(
               ^^^^^^^^^^^^^^^^^^^^^^^^^^^^^^^^^^^^
        model=model, contents=contents, config=config
        ^^^^^^^^^^^^^^^^^^^^^^^^^^^^^^^^^^^^^^^^^^^^^
    )
    ^
  File "C:\Users\past9\AppData\Local\Programs\Python\Python313\Lib\site-packages\google\genai\models.py", line 6539, in _generate_content_stream
    response_stream = await self._api_client.async_request_streamed(
                      ^^^^^^^^^^^^^^^^^^^^^^^^^^^^^^^^^^^^^^^^^^^^^^
        'post', path, request_dict, http_options
        ^^^^^^^^^^^^^^^^^^^^^^^^^^^^^^^^^^^^^^^^
    )
    ^
  File "C:\Users\past9\AppData\Local\Programs\Python\Python313\Lib\site-packages\google\genai\_api_client.py", line 836, in async_request_streamed
    response = await self._async_request(http_request=http_request, stream=True)
               ^^^^^^^^^^^^^^^^^^^^^^^^^^^^^^^^^^^^^^^^^^^^^^^^^^^^^^^^^^^^^^^^^
  File "C:\Users\past9\AppData\Local\Programs\Python\Python313\Lib\site-packages\google\genai\_api_client.py", line 751, in _async_request
    await errors.APIError.raise_for_async_response(response)
  File "C:\Users\past9\AppData\Local\Programs\Python\Python313\Lib\site-packages\google\genai\errors.py", line 129, in raise_for_async_response
    raise ClientError(status_code, response_json, response)
google.genai.errors.ClientError: 400 INVALID_ARGUMENT. {'error': {'code': 400, 'message': '* GenerateContentRequest.contents[11].parts: contents.parts must not be empty.\n', 'status': 'INVALID_ARGUMENT'}}
❯ : what happpened
┏━ ● You (04:02:39) ━━━━━━━━━━━━━━━━━━━━━━━━━━━━━━━━━━━━━━━━━━━━━━━━━━━━━━━━━━━━━━━━━━━━━━━━━━━━━━━━━━━━━━━━━━━━━━━━━━━┓
┃                                                                                                                      ┃
┃  what happpened                                                                                                      ┃
┃                                                                                                                      ┃
┗━━━━━━━━━━━━━━━━━━━━━━━━━━━━━━━━━━━━━━━━━━━━━━━━━━━━━━━━━━━━━━━━━━━━━━━━━━━━━━━━━━━━━━━━━━━━━━━━━━━━━━━━━━━━━━━━━━━━━━┛
╭─ ✕ Error (04:02:40) ─────────────────────────────────────────────────────────────────────────────────────────────────╮
│                                                                                                                      │
│  An API error occurred: 400 INVALID_ARGUMENT. {'error': {'code': 400, 'message': '*                                  │
│  GenerateContentRequest.contents[11].parts: contents.parts must not be empty.\n', 'status': 'INVALID_ARGUMENT'}}     │
│                                                                                                                      │
╰──────────────────────────────────────────────────────────────────────────────────────────────────────────────────────╯
Traceback (most recent call last):
  File "C:\Users\past9\OneDrive\Desktop\project\clia\gui\main.py", line 149, in main
    async for chunk in stream:
    ...<46 lines>...
            break
  File "C:\Users\past9\AppData\Local\Programs\Python\Python313\Lib\site-packages\google\genai\models.py", line 7614, in async_generator
    response = await self._generate_content_stream(
               ^^^^^^^^^^^^^^^^^^^^^^^^^^^^^^^^^^^^
        model=model, contents=contents, config=config
        ^^^^^^^^^^^^^^^^^^^^^^^^^^^^^^^^^^^^^^^^^^^^^
    )
    ^
  File "C:\Users\past9\AppData\Local\Programs\Python\Python313\Lib\site-packages\google\genai\models.py", line 6539, in _generate_content_stream
    response_stream = await self._api_client.async_request_streamed(
                      ^^^^^^^^^^^^^^^^^^^^^^^^^^^^^^^^^^^^^^^^^^^^^^
        'post', path, request_dict, http_options
        ^^^^^^^^^^^^^^^^^^^^^^^^^^^^^^^^^^^^^^^^
    )
    ^
  File "C:\Users\past9\AppData\Local\Programs\Python\Python313\Lib\site-packages\google\genai\_api_client.py", line 836, in async_request_streamed
    response = await self._async_request(http_request=http_request, stream=True)
               ^^^^^^^^^^^^^^^^^^^^^^^^^^^^^^^^^^^^^^^^^^^^^^^^^^^^^^^^^^^^^^^^^
  File "C:\Users\past9\AppData\Local\Programs\Python\Python313\Lib\site-packages\google\genai\_api_client.py", line 751, in _async_request
    await errors.APIError.raise_for_async_response(response)
  File "C:\Users\past9\AppData\Local\Programs\Python\Python313\Lib\site-packages\google\genai\errors.py", line 129, in raise_for_async_response
    raise ClientError(status_code, response_json, response)
google.genai.errors.ClientError: 400 INVALID_ARGUMENT. {'error': {'code': 400, 'message': '* GenerateContentRequest.contents[11].parts: contents.parts must not be empty.\n', 'status': 'INVALID_ARGUMENT'}}
❯ :